Workbook

Sheet WA_Fn-UseC_-HR-Employee-Attriti
A1: Age | B1: Attrition | C1: BusinessTravel | D1: DailyRate | E1: Department | F1: DistanceFromHome | G1: Education | H1: EducationField | I1: EmployeeCount | J1: EmployeeNumber | K1: EnvironmentSatisfaction | L1: Gender | M1: HourlyRate | N1: JobInvolvement | O1: JobLevel | P1: JobRole | Q1: JobSatisfaction | R1: MaritalStatus | S1: MonthlyIncome | T1: MonthlyRate | U1: NumCompaniesWorked | V1: Over18 | W1: OverTime | X1: PercentSalaryHike | Y1: PerformanceRating | Z1: RelationshipSatisfaction | AA1: StandardHours | AB1: StockOptionLevel | AC1: TotalWorkingYears | AD1: TrainingTimesLastYear | AE1: WorkLifeBalance | AF1: YearsAtCompany | AG1: YearsInCurrentRole | AH1: YearsSinceLastPromotion | AI1: YearsWithCurrManager
A2: 41 | B2: Yes | C2: Travel_Rarely | D2: 1102 | E2: Sales | F2: 1 | G2: 2 | H2: Life Sciences | I2: 1 | J2: 1 | K2: 2 | L2: Female | M2: 94 | N2: 3 | O2: 2 | P2: Sales Executive | Q2: 4 | R2: Single | S2: 5993 | T2: 19479 | U2: 8 | V2: Y | W2: Yes | X2: 11 | Y2: 3 | Z2: 1 | AA2: 80 | AB2: 0 | AC2: 8 | AD2: 0 | AE2: 1 | AF2: 6 | AG2: 4 | AH2: 0 | AI2: 5
A3: 49 | B3: No | C3: Travel_Frequently | D3: 279 | E3: Research & Development | F3: 8 | G3: 1 | H3: Life Sciences | I3: 1 | J3: 2 | K3: 3 | L3: Male | M3: 61 | N3: 2 | O3: 2 | P3: Research Scientist | Q3: 2 | R3: Married | S3: 5130 | T3: 24907 | U3: 1 | V3: Y | W3: No | X3: 23 | Y3: 4 | Z3: 4 | AA3: 80 | AB3: 1 | AC3: 10 | AD3: 3 | AE3: 3 | AF3: 10 | AG3: 7 | AH3: 1 | AI3: 7
A4: 37 | B4: Yes | C4: Travel_Rarely | D4: 1373 | E4: Research & Development | F4: 2 | G4: 2 | H4: Other | I4: 1 | J4: 4 | K4: 4 | L4: Male | M4: 92 | N4: 2 | O4: 1 | P4: Laboratory Technician | Q4: 3 | R4: Single | S4: 2090 | T4: 2396 | U4: 6 | V4: Y | W4: Yes | X4: 15 | Y4: 3 | Z4: 2 | AA4: 80 | AB4: 0 | AC4: 7 | AD4: 3 | AE4: 3 | AF4: 0 | AG4: 0 | AH4: 0 | AI4: 0
A5: 33 | B5: No | C5: Travel_Frequently | D5: 1392 | E5: Research & Development | F5: 3 | G5: 4 | H5: Life Sciences | I5: 1 | J5: 5 | K5: 4 | L5: Female | M5: 56 | N5: 3 | O5: 1 | P5: Research Scientist | Q5: 3 | R5: Married | S5: 2909 | T5: 23159 | U5: 1 | V5: Y | W5: Yes | X5: 11 | Y5: 3 | Z5: 3 | AA5: 80 | AB5: 0 | AC5: 8 | AD5: 3 | AE5: 3 | AF5: 8 | AG5: 7 | AH5: 3 | AI5: 0
A6: 27 | B6: No | C6: Travel_Rarely | D6: 591 | E6: Research & Development | F6: 2 | G6: 1 | H6: Medical | I6: 1 | J6: 7 | K6: 1 | L6: Male | M6: 40 | N6: 3 | O6: 1 | P6: Laboratory Technician | Q6: 2 | R6: Married | S6: 3468 | T6: 16632 | U6: 9 | V6: Y | W6: No | X6: 12 | Y6: 3 | Z6: 4 | AA6: 80 | AB6: 1 | AC6: 6 | AD6: 3 | AE6: 3 | AF6: 2 | AG6: 2 | AH6: 2 | AI6: 2
A7: 32 | B7: No | C7: Travel_Frequently | D7: 1005 | E7: Research & Development | F7: 2 | G7: 2 | H7: Life Sciences | I7: 1 | J7: 8 | K7: 4 | L7: Male | M7: 79 | N7: 3 | O7: 1 | P7: Laboratory Technician | Q7: 4 | R7: Single | S7: 3068 | T7: 11864 | U7: 0 | V7: Y | W7: No | X7: 13 | Y7: 3 | Z7: 3 | AA7: 80 | AB7: 0 | AC7: 8 | AD7: 2 | AE7: 2 | AF7: 7 | AG7: 7 | AH7: 3 | AI7: 6
A8: 59 | B8: No | C8: Travel_Rarely | D8: 1324 | E8: Research & Development | F8: 3 | G8: 3 | H8: Medical | I8: 1 | J8: 10 | K8: 3 | L8: Female | M8: 81 | N8: 4 | O8: 1 | P8: Laboratory Technician | Q8: 1 | R8: Married | S8: 2670 | T8: 9964 | U8: 4 | V8: Y | W8: Yes | X8: 20 | Y8: 4 | Z8: 1 | AA8: 80 | AB8: 3 | AC8: 12 | AD8: 3 | AE8: 2 | AF8: 1 | AG8: 0 | AH8: 0 | AI8: 0
A9: 30 | B9: No | C9: Travel_Rarely | D9: 1358 | E9: Research & Development | F9: 24 | G9: 1 | H9: Life Sciences | I9: 1 | J9: 11 | K9: 4 | L9: Male | M9: 67 | N9: 3 | O9: 1 | P9: Laboratory Technician | Q9: 3 | R9: Divorced | S9: 2693 | T9: 13335 | U9: 1 | V9: Y | W9: No | X9: 22 | Y9: 4 | Z9: 2 | AA9: 80 | AB9: 1 | AC9: 1 | AD9: 2 | AE9: 3 | AF9: 1 | AG9: 0 | AH9: 0 | AI9: 0
A10: 38 | B10: No | C10: Travel_Frequently | D10: 216 | E10: Research & Development | F10: 23 | G10: 3 | H10: Life Sciences | I10: 1 | J10: 12 | K10: 4 | L10: Male | M10: 44 | N10: 2 | O10: 3 | P10: Manufacturing Director | Q10: 3 | R10: Single | S10: 9526 | T10: 8787 | U10: 0 | V10: Y | W10: No | X10: 21 | Y10: 4 | Z10: 2 | AA10: 80 | AB10: 0 | AC10: 10 | AD10: 2 | AE10: 3 | AF10: 9 | AG10: 7 | AH10: 1 | AI10: 8
A11: 36 | B11: No | C11: Travel_Rarely | D11: 1299 | E11: Research & Development | F11: 27 | G11: 3 | H11: Medical | I11: 1 | J11: 13 | K11: 3 | L11: Male | M11: 94 | N11: 3 | O11: 2 | P11: Healthcare Representative | Q11: 3 | R11: Married | S11: 5237 | T11: 16577 | U11: 6 | V11: Y | W11: No | X11: 13 | Y11: 3 | Z11: 2 | AA11: 80 | AB11: 2 | AC11: 17 | AD11: 3 | AE11: 2 | AF11: 7 | AG11: 7 | AH11: 7 | AI11: 7
A12: 35 | B12: No | C12: Travel_Rarely | D12: 809 | E12: Research & Development | F12: 16 | G12: 3 | H12: Medical | I12: 1 | J12: 14 | K12: 1 | L12: Male | M12: 84 | N12: 4 | O12: 1 | P12: Laboratory Technician | Q12: 2 | R12: Married | S12: 2426 | T12: 16479 | U12: 0 | V12: Y | W12: No | X12: 13 | Y12: 3 | Z12: 3 | AA12: 80 | AB12: 1 | AC12: 6 | AD12: 5 | AE12: 3 | AF12: 5 | AG12: 4 | AH12: 0 | AI12: 3
A13: 29 | B13: No | C13: Travel_Rarely | D13: 153 | E13: Research & Development | F13: 15 | G13: 2 | H13: Life Sciences | I13: 1 | J13: 15 | K13: 4 | L13: Female | M13: 49 | N13: 2 | O13: 2 | P13: Laboratory Technician | Q13: 3 | R13: Single | S13: 4193 | T13: 12682 | U13: 0 | V13: Y | W13: Yes | X13: 12 | Y13: 3 | Z13: 4 | AA13: 80 | AB13: 0 | AC13: 10 | AD13: 3 | AE13: 3 | AF13: 9 | AG13: 5 | AH13: 0 | AI13: 8
... A1471: 34 | B1471: No | C1471: Travel_Rarely | D1471: 628 | E1471: Research & Development | F1471: 8 | G1471: 3 | H1471: Medical | I1471: 1 | J1471: 2068 | K1471: 2 | L1471: Male | M1471: 82 | N1471: 4 | O1471: 2 | P1471: Laboratory Technician | Q1471: 3 | R1471: Married | S1471: 4404 | T1471: 10228 | U1471: 2 | V1471: Y | W1471: No | X1471: 12 | Y1471: 3 | Z1471: 1 | AA1471: 80 | AB1471: 0 | AC1471: 6 | AD1471: 3 | AE1471: 4 | AF1471: 4 | AG1471: 3 | AH1471: 1 | AI1471: 2

Sheet Dataset_Overview
A1: HR EMPLOYEE ATTRITION ANALYTICS PROJECT — DATASET OVERVIEW & JUSTIFICATION
A3: Dataset Name | B3: IBM HR Analytics Employee Attrition & Performance
A4: Source | B4: Kaggle (fictional dataset created by IBM data scientists)
A5: Link | B5: https://www.kaggle.com/datasets/pavansubhasht/ibm-hr-analytics-attrition-dataset
A6: Records | B6: =COUNTA(Data_RawIssues!A:A)-1 -> 1485
A7: Columns | B7: 35
A9: BUSINESS CONTEXT
A10: Employee attrition (voluntary/involuntary turnover) is one of the costliest problems in workforce management. Industry studies estimate replacing a single employee costs 50%-200% of their annual salary once recruiting, onboarding, lost productivity and knowledge loss are accounted for. IBM compiled this dataset (with fictional but realistic employee records) to let analysts study the drivers of attrition across a large, multi-department organization spanning Sales, Research & Development, and Human Resources.
A12: BUSINESS PROBLEM
A13: HR leadership needs to understand which employees are at the highest risk of leaving, why they leave, and which levers (compensation, work-life balance, career progression, overtime policy) the company can pull to retain high-value talent before attrition happens rather than reacting after the fact.
A15: ANALYTICAL OBJECTIVES
A16: 1. Quantify attrition rate overall and by department, job role, and demographic segment.
A17: 2. Identify the strongest statistical drivers of attrition (satisfaction, income, overtime, tenure, commute distance, promotion history).
A18: 3. Build a predictive model that flags individual employees at elevated attrition risk.
A19: 4. Translate findings into KPIs and a monitoring dashboard for ongoing HR decision-making.
A21: WHY THE TARGET VARIABLE (Attrition) IS SUITABLE
A22: Attrition is a binary Yes/No field recorded for every employee, giving a clean, unambiguous label for supervised classification. It is directly actionable (HR can intervene on a per-employee basis), commercially meaningful (turnover cost is a measurable P&L line), and it is influenced by a rich mix of numeric (income, tenure, satisfaction scores) and categorical (department, job role, marital status, overtime) predictors, making it ideal for both statistical EDA and machine learning.
A24: WHY THIS DATASET IS APPROPRIATE
... A28: A working attrition-risk model lets HR prioritize retention spend (counter-offers, flexible work, promotion cycles) on the employees most likely to leave, rather than applying blanket policies. Even a modest reduction in voluntary attrition among high performers translates directly into avoided replacement cost, preserved institutional knowledge, and improved team morale.

Sheet Cleaning_Log
A1: DATA CLEANING LOG
A2: Source: Data_RawIssues (1,485 rows incl. 15 injected duplicates) → Output: Data_Cleaned (1,470 rows)
A4: # | B4: Issue Type | C4: Column(s) Affected | D4: Count | E4: Why It Matters | F4: Example BEFORE | G4: Cleaning Action | H4: Example AFTER
A5: 1 | B5: Missing values | C5: MonthlyIncome, EnvironmentSatisfaction, Department, TotalWorkingYears, BusinessTravel | D5: 40 | E5: Blanks break aggregation (SUM/AVERAGE silently skip or error) and would bias any ML model trained on incomplete rows. | F5: Data_RawIssues!S12 = (blank) | G5: Numeric fields imputed with median (overall or by JobLevel); categorical fields imputed with mode (most frequent category). | H5: Data_Cleaned!S11 = 5343 (JobLevel-2 median income)
A6: 2 | B6: Duplicate records | C6: All 35 columns (whole row) | D6: 15 | E6: Duplicate employee rows double-count that person in headcount, attrition-rate and payroll aggregations, inflating every downstream metric. | F6: EmployeeNumber 8 appears in rows 9 and 1472 | G6: Dropped duplicate rows, keeping first occurrence per EmployeeNumber (drop_duplicates(subset='EmployeeNumber', keep='first')). | H6: 1,485 rows → 1,470 unique employees
A7: 3 | B7: Inconsistent categorical text | C7: Department, Gender, OverTime, MaritalStatus, BusinessTravel | D7: 21 | E7: "Sales", "sales", "SALES" and "Sales " are treated as 4 distinct categories by GROUP BY/pivot logic and by one-hot encoders, fragmenting the true signal. | F7: Data_RawIssues!E102 = "sales"; E202="SALES"; E302="Research & Development " | G7: Trimmed whitespace, standardized casing, and mapped abbreviations/synonyms to one canonical label per category via a lookup dictionary. | H7: Data_Cleaned!E101 = "Sales" (all variants unified)
A8: 4 | B8: Incorrect data types (numbers stored as text) | C8: Age, MonthlyIncome, DistanceFromHome, PercentSalaryHike | D8: 10 | E8: Text-typed numerics fail arithmetic and are silently excluded from SUM/AVERAGE/correlation calculations, and break ML feature matrices which require numeric dtypes. | F8: Data_RawIssues!A27 = "35 years"; S56="$5,993"; S76="6500 USD" | G8: Extracted the numeric substring (regex \d+), stripped currency symbols/commas/unit suffixes, cast to float/int. | H8: Data_Cleaned!A26 = 35 (numeric)
A9: 5 | B9: Outliers | C9: Age, MonthlyIncome, DistanceFromHome, NumCompaniesWorked, TotalWorkingYears | D9: 8 | E9: Implausible values (Age=202, MonthlyIncome=$999,999, negative commute distance) distort means/std-devs and can dominate distance-based models or tree splits. | F9: Data_RawIssues!A502=150; A602=202; A702=-5; S802=999999; S902=100; F1002=-10; U1102=99; AC1202=80 | G9: Applied business-rule bounds (Age 18-75, MonthlyIncome $1,000-$20,000, TotalWorkingYears ≤ 45, NumCompaniesWorked ≤ 15). Values outside bounds treated as missing, then median-imputed. Negative DistanceFromHome corrected via absolute value (sign-flip error). | H9: Data_Cleaned!A501=36 (median); S801=9950 (JobLevel median); F1001=10
A10: 6 | B10: Scale/unit corruption (percentage stored as decimal fraction) | C10: PercentSalaryHike | D10: 2 | E10: Discovered during verification: when the injected text values "11%"/"14%" were entered into a spreadsheet cell, Excel auto-parsed them as percentage-formatted numbers (0.11 / 0.14) rather than the whole numbers 11 / 14. This is a common real-world spreadsheet data-entry trap that silently divides values by 100. | F10: Data_RawIssues!X107 = 0.11 (displayed as "11%") | G10: Applied a rule: any PercentSalaryHike value < 1 (outside the column's natural 11-25 range) is a scale error — multiplied by 100 and reformatted as a whole number. | H10: Data_Cleaned!X106 = 11
A12: EQUIVALENT PYTHON (PANDAS/NUMPY) CLEANING PIPELINE
A13: import pandas as pd import numpy as np import re df = pd.read_csv('HR_Employee_Attrition_RawIssues.csv') print(df.shape) # (1485, 35) -- includes 15 injected duplicates print(df.dtypes) print(df.isnull().sum()) # missing-value audit # --- 1. Fix incorrect data types (strip units/currency, cast to numeric) --- def to_numeric(series): return series.apply(lambda v: float(re.search(r'-?\d+(\.\d+)?', str(v).replace(',', '')).group()) if pd.notna(v) and str(v).strip() != '' else np.nan) for col in ['Age', 'MonthlyIncome', 'DistanceFromHome', 'PercentSalaryHike']: df[col] = to_numeric(df[col]) # --- 2. Standardize inconsistent categorical text --- def clean_cat(series, mapping): s = series.astype(str).str.strip().str.lower() return s.map(mapping).fillna(series.astype(str).str.strip()) dept_map = {'sales': 'Sales', 'research & development': 'Research & Development', 'human resources': 'Human Resources', 'r&d': 'Research & Development'} gender_map = {'m': 'Male', 'f': 'Female', 'male': 'Male', 'female': 'Female'} overtime_map = {'yes': 'Yes', 'no': 'No'} marital_map = {'single': 'Single', 'married': 'Married', 'divorced': 'Divorced'} travel_map = {'travel_rarely': 'Travel_Rarely', 'travel_frequently': 'Travel_Frequently', 'non-travel': 'Non-Travel'} df['Department'] = clean_cat(df['Department'], dept_map) df['Gender'] = clean_cat(df['Gender'], gender_map) df['OverTime'] = clean_cat(df['OverTime'], overtime_map) df['MaritalStatus'] = clean_cat(df['MaritalStatus'], marital_map) df['BusinessTravel'] = clean_cat(df['BusinessTravel'], travel_map) # --- 3. Outlier detection & correction (business-rule bounds) --- df.loc[(df['Age'] < 18) | (df['Age'] > 75), 'Age'] = np.nan df.loc[(df['MonthlyIncome'] < 1000) | (df['MonthlyIncome'] > 20000), 'MonthlyIncome'] = np.nan df.loc[df['NumCompaniesWorked'] > 15, 'NumCompaniesWorked'] = np.nan df.loc[df['TotalWorkingYears'] > 45, 'TotalWorkingYears'] = np.nan df['DistanceFromHome'] = df['DistanceFromHome'].abs() # sign-flip correction # --- 4. Impute missing values (median for numeric, mode for categorical) --- df['Age'] = df['Age'].fillna(df['Age'].median()) df['MonthlyIncome'] = df.groupby('JobLevel')['MonthlyIncome'].transform(lambda x: x.fillna(x.median())) df['TotalWorkingYears'] = df['TotalWorkingYears'].fillna(df['TotalWorkingYears'].median()) df['NumCompaniesWorked'] = df['NumCompaniesWorked'].fillna(df['NumCompaniesWorked'].median()) df['EnvironmentSatisfaction'] = df['EnvironmentSatisfaction'].fillna(df['EnvironmentSatisfaction'].mode()[0]) df['Department'] = df['Department'].fillna(df['Department'].mode()[0]) df['BusinessTravel'] = df['BusinessTravel'].fillna(df['BusinessTravel'].mode()[0]) # --- 5. Remove duplicate records --- df = df.drop_duplicates(subset='EmployeeNumber', keep='first') print(df.shape) # (1470, 35) # --- 6. Encode categorical variables --- df['Attrition_Flag'] = (df['Attrition'] == 'Yes').astype(int) df['OverTime_Flag'] = (df['OverTime'] == 'Yes').astype(int) df_encoded = pd.get_dummies(df, columns=['Department', 'JobRole', 'MaritalStatus', 'EducationField', 'BusinessTravel', 'Gender'], drop_first=True) # --- 7. Feature scaling (for distance-based/linear models) --- from sklearn.preprocessing import StandardScaler num_cols = ['MonthlyIncome', 'Age', 'DistanceFromHome', 'TotalWorkingYears'] scaler = StandardScaler() df_encoded[[c + '_scaled' for c in num_cols]] = scaler.fit_transform(df_encoded[num_cols]) # --- 8. Feature engineering --- df['SatisfactionIndex'] = df[['EnvironmentSatisfaction','JobSatisfaction', 'RelationshipSatisfaction','WorkLifeBalance']].mean(axis=1) df['IncomePerYearAtCompany'] = df['MonthlyIncome'] * 12 / (df['YearsAtCompany'] + 1) df['TenureRatio'] = df['YearsAtCompany'] / (df['TotalWorkingYears'] + 1) df['AgeGroup'] = pd.cut(df['Age'], bins=[0,30,40,50,100], labels=['Under 30','30-39','40-49','50+']) df['IncomeBand'] = pd.qcut(df['MonthlyIncome'], 4, labels=['Low','Medium','High','Very High']) df.to_csv('HR_Employee_Attrition_Cleaned.csv', index=False)
A15: AI-ASSISTED RECOMMENDATIONS FOR FURTHER DATA QUALITY IMPROVEMENT
A16: 1. Add data-entry validation (dropdown lists / controlled vocabularies) at the HRIS source system for Department, Gender, MaritalStatus, BusinessTravel and OverTime to prevent free-text variants from ever entering the warehouse.
A17: 2. Enforce numeric field types at ingestion (schema validation e.g. Great Expectations / Pandera) so Age, MonthlyIncome, DistanceFromHome and PercentSalaryHike cannot be saved as text with units or currency symbols.
A18: 3. Add a uniqueness constraint on EmployeeNumber in the source database to block duplicate record insertion at the point of entry rather than relying on downstream de-duplication.
A19: 4. Implement automated range checks (e.g. Age 18-75, MonthlyIncome within organizational pay bands) as a nightly data-quality job, flagging violations for HR review before they reach analytics tables.
A20: 5. Track a data-quality score per refresh (missing %, duplicate %, out-of-range %) on a monitoring dashboard so degradation is caught immediately rather than discovered during analysis.
A21: 6. For MonthlyIncome imputation specifically, prefer group-wise (JobLevel) medians over a single global median — income varies enormously by level, and a global median would systematically misstate compensation for junior/senior employees alike.

Sheet Data_RawIssues
A1: Age | B1: Attrition | C1: BusinessTravel | D1: DailyRate | E1: Department | F1: DistanceFromHome | G1: Education | H1: EducationField | I1: EmployeeCount | J1: EmployeeNumber | K1: EnvironmentSatisfaction | L1: Gender | M1: HourlyRate | N1: JobInvolvement | O1: JobLevel | P1: JobRole | Q1: JobSatisfaction | R1: MaritalStatus | S1: MonthlyIncome | T1: MonthlyRate | U1: NumCompaniesWorked | V1: Over18 | W1: OverTime | X1: PercentSalaryHike | Y1: PerformanceRating | Z1: RelationshipSatisfaction | AA1: StandardHours | AB1: StockOptionLevel | AC1: TotalWorkingYears | AD1: TrainingTimesLastYear | AE1: WorkLifeBalance | AF1: YearsAtCompany | AG1: YearsInCurrentRole | AH1: YearsSinceLastPromotion | AI1: YearsWithCurrManager
A2: 41 | B2: Yes | C2: Travel_Rarely | D2: 1102 | E2: Sales | F2: 1 | G2: 2 | H2: Life Sciences | I2: 1 | J2: 1 | K2: 2 | L2: Female | M2: 94 | N2: 3 | O2: 2 | P2: Sales Executive | Q2: 4 | R2: Single | S2: 5993 | T2: 19479 | U2: 8 | V2: Y | W2: Yes | X2: 11 | Y2: 3 | Z2: 1 | AA2: 80 | AB2: 0 | AC2: 8 | AD2: 0 | AE2: 1 | AF2: 6 | AG2: 4 | AH2: 0 | AI2: 5
A3: 49 | B3: No | C3: Travel_Frequently | D3: 279 | E3: Research & Development | F3: 8 | G3: 1 | H3: Life Sciences | I3: 1 | J3: 2 | K3: 3 | L3: Male | M3: 61 | N3: 2 | O3: 2 | P3: Research Scientist | Q3: 2 | R3: Married | S3: 5130 | T3: 24907 | U3: 1 | V3: Y | W3: No | X3: 23 | Y3: 4 | Z3: 4 | AA3: 80 | AB3: 1 | AC3: 10 | AD3: 3 | AE3: 3 | AF3: 10 | AG3: 7 | AH3: 1 | AI3: 7
A4: 37 | B4: Yes | C4: Travel_Rarely | D4: 1373 | E4: Research & Development | F4: 2 | G4: 2 | H4: Other | I4: 1 | J4: 4 | K4: 4 | L4: Male | M4: 92 | N4: 2 | O4: 1 | P4: Laboratory Technician | Q4: 3 | R4: Single | S4: 2090 | T4: 2396 | U4: 6 | V4: Y | W4: Yes | X4: 15 | Y4: 3 | Z4: 2 | AA4: 80 | AB4: 0 | AC4: 7 | AD4: 3 | AE4: 3 | AF4: 0 | AG4: 0 | AH4: 0 | AI4: 0
A5: 33 | B5: No | C5: Travel_Frequently | D5: 1392 | E5: Research & Development | F5: 3 | G5: 4 | H5: Life Sciences | I5: 1 | J5: 5 | K5: 4 | L5: Female | M5: 56 | N5: 3 | O5: 1 | P5: Research Scientist | Q5: 3 | R5: Married | S5: 2909 | T5: 23159 | U5: 1 | V5: Y | W5: Yes | X5: 11 | Y5: 3 | Z5: 3 | AA5: 80 | AB5: 0 | AC5: 8 | AD5: 3 | AE5: 3 | AF5: 8 | AG5: 7 | AH5: 3 | AI5: 0
A6: 27 | B6: No | C6: Travel_Rarely | D6: 591 | E6: Research & Development | F6: 2 | G6: 1 | H6: Medical | I6: 1 | J6: 7 | K6: 1 | L6: Male | M6: 40 | N6: 3 | O6: 1 | P6: Laboratory Technician | Q6: 2 | R6: Married | S6: 3468 | T6: 16632 | U6: 9 | V6: Y | W6: No | X6: 12 | Y6: 3 | Z6: 4 | AA6: 80 | AB6: 1 | AC6: 6 | AD6: 3 | AE6: 3 | AF6: 2 | AG6: 2 | AH6: 2 | AI6: 2
A7: 32 | B7: No | C7: Travel_Frequently | D7: 1005 | E7: Research & Development | F7: 2 | G7: 2 | H7: Life Sciences | I7: 1 | J7: 8 | K7: 4 | L7: Male | M7: 79 | N7: 3 | O7: 1 | P7: Laboratory Technician | Q7: 4 | R7: Single | S7: 3068 | T7: 11864 | U7: 0 | V7: Y | W7: No | X7: 13 | Y7: 3 | Z7: 3 | AA7: 80 | AB7: 0 | AC7: 8 | AD7: 2 | AE7: 2 | AF7: 7 | AG7: 7 | AH7: 3 | AI7: 6
A8: 59 | B8: No | C8: Travel_Rarely | D8: 1324 | E8: Research & Development | F8: 3 | G8: 3 | H8: Medical | I8: 1 | J8: 10 | K8: 3 | L8: Female | M8: 81 | N8: 4 | O8: 1 | P8: Laboratory Technician | Q8: 1 | R8: Married | S8: 2670 | T8: 9964 | U8: 4 | V8: Y | W8: Yes | X8: 20 | Y8: 4 | Z8: 1 | AA8: 80 | AB8: 3 | AC8: 12 | AD8: 3 | AE8: 2 | AF8: 1 | AG8: 0 | AH8: 0 | AI8: 0
A9: 30 | B9: No | C9: Travel_Rarely | D9: 1358 | E9: Research & Development | F9: 24 | G9: 1 | H9: Life Sciences | I9: 1 | J9: 11 | K9: 4 | L9: Male | M9: 67 | N9: 3 | O9: 1 | P9: Laboratory Technician | Q9: 3 | R9: Divorced | S9: 2693 | T9: 13335 | U9: 1 | V9: Y | W9: No | X9: 22 | Y9: 4 | Z9: 2 | AA9: 80 | AB9: 1 | AC9: 1 | AD9: 2 | AE9: 3 | AF9: 1 | AG9: 0 | AH9: 0 | AI9: 0
A10: 38 | B10: No | C10: Travel_Frequently | D10: 216 | E10: Research & Development | F10: 23 | G10: 3 | H10: Life Sciences | I10: 1 | J10: 12 | K10: 4 | L10: Male | M10: 44 | N10: 2 | O10: 3 | P10: Manufacturing Director | Q10: 3 | R10: Single | S10: 9526 | T10: 8787 | U10: 0 | V10: Y | W10: No | X10: 21 | Y10: 4 | Z10: 2 | AA10: 80 | AB10: 0 | AC10: 10 | AD10: 2 | AE10: 3 | AF10: 9 | AG10: 7 | AH10: 1 | AI10: 8
A11: 36 | B11: No | C11: Travel_Rarely | D11: 1299 | E11: Research & Development | F11: 27 | G11: 3 | H11: Medical | I11: 1 | J11: 13 | K11: 3 | L11: Male | M11: 94 | N11: 3 | O11: 2 | P11: Healthcare Representative | Q11: 3 | R11: Married | S11: 5237 | T11: 16577 | U11: 6 | V11: Y | W11: No | X11: 13 | Y11: 3 | Z11: 2 | AA11: 80 | AB11: 2 | AC11: 17 | AD11: 3 | AE11: 2 | AF11: 7 | AG11: 7 | AH11: 7 | AI11: 7
A12: 35 | B12: No | C12: Travel_Rarely | D12: 809 | E12: Research & Development | F12: 16 | G12: 3 | H12: Medical | I12: 1 | J12: 14 | K12: 1 | L12: Male | M12: 84 | N12: 4 | O12: 1 | P12: Laboratory Technician | Q12: 2 | R12: Married | T12: 16479 | U12: 0 | V12: Y | W12: No | X12: 13 | Y12: 3 | Z12: 3 | AA12: 80 | AB12: 1 | AC12: 6 | AD12: 5 | AE12: 3 | AF12: 5 | AG12: 4 | AH12: 0 | AI12: 3
A13: 29 | B13: No | C13: Travel_Rarely | D13: 153 | E13: Research & Development | F13: 15 | G13: 2 | H13: Life Sciences | I13: 1 | J13: 15 | K13: 4 | L13: Female | M13: 49 | N13: 2 | O13: 2 | P13: Laboratory Technician | Q13: 3 | R13: Single | S13: 4193 | T13: 12682 | U13: 0 | V13: Y | W13: Yes | X13: 12 | Y13: 3 | Z13: 4 | AA13: 80 | AB13: 0 | AC13: 10 | AD13: 3 | AE13: 3 | AF13: 9 | AG13: 5 | AH13: 0 | AI13: 8
A14: 31 | B14: No | C14: Travel_Rarely | D14: 670 | E14: Research & Development | F14: 26 | G14: 1 | H14: Life Sciences | I14: 1 | J14: 16 | K14: 1 | L14: Male | M14: 31 | N14: 3 | O14: 1 | P14: Research Scientist | Q14: 3 | R14: Divorced | S14: 2911 | T14: 15170 | U14: 1 | V14: Y | W14: No | X14: 17 | Y14: 3 | Z14: 4 | AA14: 80 | AB14: 1 | AC14: 5 | AD14: 1 | AE14: 2 | AF14: 5 | AG14: 2 | AH14: 4 | AI14: 3
A15: 34 | B15: No | C15: Travel_Rarely | D15: 1346 | E15: Research & Development | F15: 19 | G15: 2 | H15: Medical | I15: 1 | J15: 18 | K15: 2 | L15: Male | M15: 93 | N15: 3 | O15: 1 | P15: Laboratory Technician | Q15: 4 | R15: Divorced | S15: 2661 | T15: 8758 | U15: 0 | V15: Y | W15: No | X15: 11 | Y15: 3 | Z15: 3 | AA15: 80 | AB15: 1 | AC15: 3 | AD15: 2 | AE15: 3 | AF15: 2 | AG15: 2 | AH15: 1 | AI15: 2
A16: 28 | B16: Yes | C16: Travel_Rarely | D16: 103 | E16: Research & Development | F16: 24 | G16: 3 | H16: Life Sciences | I16: 1 | J16: 19 | K16: 3 | L16: Male | M16: 50 | N16: 2 | O16: 1 | P16: Laboratory Technician | Q16: 3 | R16: Single | S16: 2028 | T16: 12947 | U16: 5 | V16: Y | W16: Yes | X16: 14 | Y16: 3 | Z16: 2 | AA16: 80 | AB16: 0 | AC16: 6 | AD16: 4 | AE16: 3 | AF16: 4 | AG16: 2 | AH16: 0 | AI16: 3
A17: 29 | B17: No | C17: Travel_Rarely | D17: 1389 | E17: Research & Development | F17: 21 | G17: 4 | H17: Life Sciences | I17: 1 | J17: 20 | L17: Female | M17: 51 | N17: 4 | O17: 3 | P17: Manufacturing Director | Q17: 1 | R17: Divorced | S17: 9980 | T17: 10195 | U17: 1 | V17: Y | W17: No | X17: 11 | Y17: 3 | Z17: 3 | AA17: 80 | AB17: 1 | AC17: 10 | AD17: 1 | AE17: 3 | AF17: 10 | AG17: 9 | AH17: 8 | AI17: 8
A18: 32 | B18: No | C18: Travel_Rarely | D18: 334 | E18: Research & Development | F18: 5 | G18: 2 | H18: Life Sciences | I18: 1 | J18: 21 | K18: 1 | L18: Male | M18: 80 | N18: 4 | O18: 1 | P18: Research Scientist | Q18: 2 | R18: Divorced | S18: 3298 | T18: 15053 | U18: 0 | V18: Y | W18: Yes | X18: 12 | Y18: 3 | Z18: 4 | AA18: 80 | AB18: 2 | AC18: 7 | AD18: 5 | AE18: 2 | AF18: 6 | AG18: 2 | AH18: 0 | AI18: 5
A19: 22 | B19: No | C19: Non-Travel | D19: 1123 | E19: Research & Development | F19: 16 | G19: 2 | H19: Medical | I19: 1 | J19: 22 | K19: 4 | L19: Male | M19: 96 | N19: 4 | O19: 1 | P19: Laboratory Technician | Q19: 4 | R19: Divorced | S19: 2935 | T19: 7324 | U19: 1 | V19: Y | W19: Yes | X19: 13 | Y19: 3 | Z19: 2 | AA19: 80 | AB19: 2 | AC19: 1 | AD19: 2 | AE19: 2 | AF19: 1 | AG19: 0 | AH19: 0 | AI19: 0
A20: 53 | B20: No | C20: Travel_Rarely | D20: 1219 | E20: Sales | F20: 2 | G20: 4 | H20: Life Sciences | I20: 1 | J20: 23 | K20: 1 | L20: Female | M20: 78 | N20: 2 | O20: 4 | P20: Manager | Q20: 4 | R20: Married | S20: 15427 | T20: 22021 | U20: 2 | V20: Y | W20: No | X20: 16 | Y20: 3 | Z20: 3 | AA20: 80 | AB20: 0 | AC20: 31 | AD20: 3 | AE20: 3 | AF20: 25 | AG20: 8 | AH20: 3 | AI20: 7
A21: 38 | B21: No | C21: Travel_Rarely | D21: 371 | E21: Research & Development | F21: 2 | G21: 3 | H21: Life Sciences | I21: 1 | J21: 24 | K21: 4 | L21: Male | M21: 45 | N21: 3 | O21: 1 | P21: Research Scientist | Q21: 4 | R21: Single | S21: 3944 | T21: 4306 | U21: 5 | V21: Y | W21: Yes | X21: 11 | Y21: 3 | Z21: 3 | AA21: 80 | AB21: 0 | AC21: 6 | AD21: 3 | AE21: 3 | AF21: 3 | AG21: 2 | AH21: 1 | AI21: 2
A22: 24 | B22: No | C22: Non-Travel | D22: 673 | E22: Research & Development | F22: 11 | G22: 2 | H22: Other | I22: 1 | J22: 26 | K22: 1 | L22: Female | M22: 96 | N22: 4 | O22: 2 | P22: Manufacturing Director | Q22: 3 | R22: Divorced | S22: 4011 | T22: 8232 | U22: 0 | V22: Y | W22: No | X22: 18 | Y22: 3 | Z22: 4 | AA22: 80 | AB22: 1 | AC22: 5 | AD22: 5 | AE22: 2 | AF22: 4 | AG22: 2 | AH22: 1 | AI22: 3
A23: 36 | B23: Yes | C23: Travel_Rarely | D23: 1218 | E23: Sales | F23: 9 | G23: 4 | H23: Life Sciences | I23: 1 | J23: 27 | K23: 3 | L23: Male | M23: 82 | N23: 2 | O23: 1 | P23: Sales Representative | Q23: 1 | R23: Single | S23: 3407 | T23: 6986 | U23: 7 | V23: Y | W23: No | X23: 23 | Y23: 4 | Z23: 2 | AA23: 80 | AB23: 0 | AC23: 10 | AD23: 4 | AE23: 3 | AF23: 5 | AG23: 3 | AH23: 0 | AI23: 3
A24: 34 | B24: No | C24: Travel_Rarely | D24: 419 | E24: Research & Development | F24: 7 | G24: 4 | H24: Life Sciences | I24: 1 | J24: 28 | K24: 1 | L24: Female | M24: 53 | N24: 3 | O24: 3 | P24: Research Director | Q24: 2 | R24: Single | S24: 11994 | T24: 21293 | U24: 0 | V24: Y | W24: No | X24: 11 | Y24: 3 | Z24: 3 | AA24: 80 | AB24: 0 | AC24: 13 | AD24: 4 | AE24: 3 | AF24: 12 | AG24: 6 | AH24: 2 | AI24: 11
A25: 21 | B25: No | C25: Travel_Rarely | D25: 391 | E25: Research & Development | F25: 15 | G25: 2 | H25: Life Sciences | I25: 1 | J25: 30 | K25: 3 | L25: Male | M25: 96 | N25: 3 | O25: 1 | P25: Research Scientist | Q25: 4 | R25: Single | S25: 1232 | T25: 19281 | U25: 1 | V25: Y | W25: No | X25: 14 | Y25: 3 | Z25: 4 | AA25: 80 | AB25: 0 | AC25: 0 | AD25: 6 | AE25: 3 | AF25: 0 | AG25: 0 | AH25: 0 | AI25: 0
A26: 34 | B26: Yes | C26: Travel_Rarely | D26: 699 | E26: Research & Development | F26: 6 | G26: 1 | H26: Medical | I26: 1 | J26: 31 | K26: 2 | L26: Male | M26: 83 | N26: 3 | O26: 1 | P26: Research Scientist | Q26: 1 | R26: Single | S26: 2960 | T26: 17102 | U26: 2 | V26: Y | W26: No | X26: 11 | Y26: 3 | Z26: 3 | AA26: 80 | AB26: 0 | AC26: 8 | AD26: 2 | AE26: 3 | AF26: 4 | AG26: 2 | AH26: 1 | AI26: 3
A27: 35 years | B27: No | C27: Travel_Rarely | D27: 1282 | E27: Research & Development | F27: 5 | G27: 3 | H27: Other | I27: 1 | J27: 32 | K27: 3 | L27: Female | M27: 58 | N27: 3 | O27: 5 | P27: Manager | Q27: 3 | R27: Divorced | S27: 19094 | T27: 10735 | U27: 4 | V27: Y | W27: No | X27: 11 | Y27: 3 | Z27: 4 | AA27: 80 | AB27: 1 | AC27: 26 | AD27: 3 | AE27: 2 | AF27: 14 | AG27: 13 | AH27: 4 | AI27: 8
A28: 32 | B28: Yes | C28: Travel_Frequently | D28: 1125 | E28: Research & Development | F28: 16 | G28: 1 | H28: Life Sciences | I28: 1 | J28: 33 | K28: 2 | L28: Female | M28: 72 | N28: 1 | O28: 1 | P28: Research Scientist | Q28: 1 | R28: Single | S28: 3919 | T28: 4681 | U28: 1 | V28: Y | W28: Yes | X28: 22 | Y28: 4 | Z28: 2 | AA28: 80 | AB28: 0 | AC28: 10 | AD28: 5 | AE28: 3 | AF28: 10 | AG28: 2 | AH28: 6 | AI28: 7
A29: 42 | B29: No | C29: Travel_Rarely | D29: 691 | E29: Sales | F29: 8 | G29: 4 | H29: Marketing | I29: 1 | J29: 35 | K29: 3 | L29: Male | M29: 48 | N29: 3 | O29: 2 | P29: Sales Executive | Q29: 2 | R29: Married | S29: 6825 | T29: 21173 | U29: 0 | V29: Y | W29: No | X29: 11 | Y29: 3 | Z29: 4 | AA29: 80 | AB29: 1 | AC29: 10 | AD29: 2 | AE29: 3 | AF29: 9 | AG29: 7 | AH29: 4 | AI29: 2
A30: 44 | B30: No | C30: Travel_Rarely | D30: 477 | E30: Research & Development | F30: 7 | G30: 4 | H30: Medical | I30: 1 | J30: 36 | K30: 1 | L30: Female | M30: 42 | N30: 2 | O30: 3 | P30: Healthcare Representative | Q30: 4 | R30: Married | S30: 10248 | T30: 2094 | U30: 3 | V30: Y | W30: No | X30: 14 | Y30: 3 | Z30: 4 | AA30: 80 | AB30: 1 | AC30: 24 | AD30: 4 | AE30: 3 | AF30: 22 | AG30: 6 | AH30: 5 | AI30: 17
A31: 46 | B31: No | C31: Travel_Rarely | D31: 705 | E31: Sales | F31: 2 | G31: 4 | H31: Marketing | I31: 1 | J31: 38 | K31: 2 | L31: Female | M31: 83 | N31: 3 | O31: 5 | P31: Manager | Q31: 1 | R31: Single | S31: 18947 | T31: 22822 | U31: 3 | V31: Y | W31: No | X31: 12 | Y31: 3 | Z31: 4 | AA31: 80 | AB31: 0 | AC31: 22 | AD31: 2 | AE31: 2 | AF31: 2 | AG31: 2 | AH31: 2 | AI31: 1
A32: 33 | B32: No | C32: Travel_Rarely | D32: 924 | E32: Research & Development | F32: 2 | G32: 3 | H32: Medical | I32: 1 | J32: 39 | K32: 3 | L32: Male | M32: 78 | N32: 3 | O32: 1 | P32: Laboratory Technician | Q32: 4 | R32: Single | S32: 2496 | T32: 6670 | U32: 4 | V32: Y | W32: No | X32: 11 | Y32: 3 | Z32: 4 | AA32: 80 | AB32: 0 | AC32: 7 | AD32: 3 | AE32: 3 | AF32: 1 | AG32: 1 | AH32: 0 | AI32: 0
A33: 44 | B33: No | C33: Travel_Rarely | D33: 1459 | E33: Research & Development | F33: 10 | G33: 4 | H33: Other | I33: 1 | J33: 40 | K33: 4 | L33: Male | M33: 41 | N33: 3 | O33: 2 | P33: Healthcare Representative | Q33: 4 | R33: Married | S33: 6465 | T33: 19121 | U33: 2 | V33: Y | W33: Yes | X33: 13 | Y33: 3 | Z33: 4 | AA33: 80 | AB33: 0 | AC33: 9 | AD33: 5 | AE33: 4 | AF33: 4 | AG33: 2 | AH33: 1 | AI33: 3
A34: 30 | B34: No | C34: Travel_Rarely | D34: 125 | E34: Research & Development | F34: 9 | G34: 2 | H34: Medical | I34: 1 | J34: 41 | K34: 4 | L34: Male | M34: 83 | N34: 2 | O34: 1 | P34: Laboratory Technician | Q34: 3 | R34: Single | S34: 2206 | T34: 16117 | U34: 1 | V34: Y | W34: No | X34: 13 | Y34: 3 | Z34: 1 | AA34: 80 | AB34: 0 | AC34: 10 | AD34: 5 | AE34: 3 | AF34: 10 | AG34: 0 | AH34: 1 | AI34: 8
A35: 39 | B35: Yes | C35: Travel_Rarely | D35: 895 | E35: Sales | F35: 5 | G35: 3 | H35: Technical Degree | I35: 1 | J35: 42 | K35: 4 | L35: Male | M35: 56 | N35: 3 | O35: 2 | P35: Sales Representative | Q35: 4 | R35: Married | S35: 2086 | T35: 3335 | U35: 3 | V35: Y | W35: No | X35: 14 | Y35: 3 | Z35: 3 | AA35: 80 | AB35: 1 | AC35: 19 | AD35: 6 | AE35: 4 | AF35: 1 | AG35: 0 | AH35: 0 | AI35: 0
A36: 24 | B36: Yes | C36: Travel_Rarely | D36: 813 | E36: Research & Development | F36: 1 | G36: 3 | H36: Medical | I36: 1 | J36: 45 | K36: 2 | L36: Male | M36: 61 | N36: 3 | O36: 1 | P36: Research Scientist | Q36: 4 | R36: Married | S36: 2293 | T36: 3020 | U36: 2 | V36: Y | W36: Yes | X36: 16 | Y36: 3 | Z36: 1 | AA36: 80 | AB36: 1 | AC36: 6 | AD36: 2 | AE36: 2 | AF36: 2 | AG36: 0 | AH36: 2 | AI36: 0
A37: 29 yrs | B37: No | C37: Travel_Rarely | D37: 1273 | E37: Research & Development | F37: 2 | G37: 2 | H37: Medical | I37: 1 | J37: 46 | K37: 4 | L37: Female | M37: 72 | N37: 4 | O37: 1 | P37: Research Scientist | Q37: 3 | R37: Divorced | S37: 2645 | T37: 21923 | U37: 1 | V37: Y | W37: No | X37: 12 | Y37: 3 | Z37: 4 | AA37: 80 | AB37: 2 | AC37: 6 | AD37: 3 | AE37: 2 | AF37: 5 | AG37: 3 | AH37: 1 | AI37: 4
A38: 50 | B38: Yes | C38: Travel_Rarely | D38: 869 | E38: Sales | F38: 3 | G38: 2 | H38: Marketing | I38: 1 | J38: 47 | K38: 1 | L38: Male | M38: 86 | N38: 2 | O38: 1 | P38: Sales Representative | Q38: 3 | R38: Married | S38: 2683 | T38: 3810 | U38: 1 | V38: Y | W38: Yes | X38: 14 | Y38: 3 | Z38: 3 | AA38: 80 | AB38: 0 | AC38: 3 | AD38: 2 | AE38: 3 | AF38: 3 | AG38: 2 | AH38: 0 | AI38: 2
A39: 35 | B39: No | C39: Travel_Rarely | D39: 890 | E39: Sales | F39: 2 | G39: 3 | H39: Marketing | I39: 1 | J39: 49 | K39: 4 | L39: Female | M39: 97 | N39: 3 | O39: 1 | P39: Sales Representative | Q39: 4 | R39: Married | S39: 2014 | T39: 9687 | U39: 1 | V39: Y | W39: No | X39: 13 | Y39: 3 | Z39: 1 | AA39: 80 | AB39: 0 | AC39: 2 | AD39: 3 | AE39: 3 | AF39: 2 | AG39: 2 | AH39: 2 | AI39: 2
A40: 36 | B40: No | C40: Travel_Rarely | D40: 852 | E40: Research & Development | F40: 5 | G40: 4 | H40: Life Sciences | I40: 1 | J40: 51 | K40: 2 | L40: Female | M40: 82 | N40: 2 | O40: 1 | P40: Research Scientist | Q40: 1 | R40: Married | S40: 3419 | T40: 13072 | U40: 9 | V40: Y | W40: Yes | X40: 14 | Y40: 3 | Z40: 4 | AA40: 80 | AB40: 1 | AC40: 6 | AD40: 3 | AE40: 4 | AF40: 1 | AG40: 1 | AH40: 0 | AI40: 0
...

Sheet Data_Cleaned
A1: Age | B1: Attrition | C1: BusinessTravel | D1: DailyRate | E1: Department | F1: DistanceFromHome | G1: Education | H1: EducationField | I1: EmployeeCount | J1: EmployeeNumber | K1: EnvironmentSatisfaction | L1: Gender | M1: HourlyRate | N1: JobInvolvement | O1: JobLevel | P1: JobRole | Q1: JobSatisfaction | R1: MaritalStatus | S1: MonthlyIncome | T1: MonthlyRate | U1: NumCompaniesWorked | V1: Over18 | W1: OverTime | X1: PercentSalaryHike | Y1: PerformanceRating | Z1: RelationshipSatisfaction | AA1: StandardHours | AB1: StockOptionLevel | AC1: TotalWorkingYears | AD1: TrainingTimesLastYear | AE1: WorkLifeBalance | AF1: YearsAtCompany | AG1: YearsInCurrentRole | AH1: YearsSinceLastPromotion | AI1: YearsWithCurrManager | AJ1: Attrition_Flag | AK1: OverTime_Flag | AL1: Gender_Flag | AM1: SatisfactionIndex | AN1: IncomePerYearAtCompany | AO1: TenureRatio | AP1: AgeGroup | AQ1: IncomeBand | AR1: CommuteBurden | AS1: IsFrequentTraveler | AU1: Income Q1 (25th pct) | AV1: =_xlfn.QUARTILE.INC($S$2:$S$1471,1) -> 2905.25
A2: 41 | B2: Yes | C2: Travel_Rarely | D2: 1102 | E2: Sales | F2: 1 | G2: 2 | H2: Life Sciences | I2: 1 | J2: 1 | K2: 2 | L2: Female | M2: 94 | N2: 3 | O2: 2 | P2: Sales Executive | Q2: 4 | R2: Single | S2: 5993 | T2: 19479 | U2: 8 | V2: Y | W2: Yes | X2: 11 | Y2: 3 | Z2: 1 | AA2: 80 | AB2: 0 | AC2: 8 | AD2: 0 | AE2: 1 | AF2: 6 | AG2: 4 | AH2: 0 | AI2: 5 | AJ2: =IF(B2="Yes",1,0) -> 1 | AK2: =IF(W2="Yes",1,0) -> 1 | AL2: =IF(L2="Male",1,0) -> 0 | AM2: =AVERAGE(K2,Q2,Z2,AE2) -> 2 | AN2: =(S2*12)/(AF2+1) -> 10273.714 | AO2: =AF2/(AC2+1) -> 0.66666667 | AP2: =IF(A2<30,"Under 30",IF(A2<40,"30-39",IF(A2<50,"40-49","50+"))) -> 40-49 | AQ2: =IF(S2<=$AV$1,"Low",IF(S2<=$AV$2,"Medium",IF(S2<=$AV$3,"High","Very High"))) -> High | AR2: =IF(F2<=5,"Short",IF(F2<=15,"Medium","Long")) -> Short | AS2: =IF(C2="Travel_Frequently",1,0) -> 0 | AU2: Income Median (50th pct) | AV2: =_xlfn.QUARTILE.INC($S$2:$S$1471,2) -> 4919
A3: 49 | B3: No | C3: Travel_Frequently | D3: 279 | E3: Research & Development | F3: 8 | G3: 1 | H3: Life Sciences | I3: 1 | J3: 2 | K3: 3 | L3: Male | M3: 61 | N3: 2 | O3: 2 | P3: Research Scientist | Q3: 2 | R3: Married | S3: 5130 | T3: 24907 | U3: 1 | V3: Y | W3: No | X3: 23 | Y3: 4 | Z3: 4 | AA3: 80 | AB3: 1 | AC3: 10 | AD3: 3 | AE3: 3 | AF3: 10 | AG3: 7 | AH3: 1 | AI3: 7 | AJ3: =IF(B3="Yes",1,0) -> 0 | AK3: =IF(W3="Yes",1,0) -> 0 | AL3: =IF(L3="Male",1,0) -> 1 | AM3: =AVERAGE(K3,Q3,Z3,AE3) -> 3 | AN3: =(S3*12)/(AF3+1) -> 5596.3636 | AO3: =AF3/(AC3+1) -> 0.90909091 | AP3: =IF(A3<30,"Under 30",IF(A3<40,"30-39",IF(A3<50,"40-49","50+"))) -> 40-49 | AQ3: =IF(S3<=$AV$1,"Low",IF(S3<=$AV$2,"Medium",IF(S3<=$AV$3,"High","Very High"))) -> High | AR3: =IF(F3<=5,"Short",IF(F3<=15,"Medium","Long")) -> Medium | AS3: =IF(C3="Travel_Frequently",1,0) -> 1 | AU3: Income Q3 (75th pct) | AV3: =_xlfn.QUARTILE.INC($S$2:$S$1471,3) -> 8339.75
A4: 37 | B4: Yes | C4: Travel_Rarely | D4: 1373 | E4: Research & Development | F4: 2 | G4: 2 | H4: Other | I4: 1 | J4: 4 | K4: 4 | L4: Male | M4: 92 | N4: 2 | O4: 1 | P4: Laboratory Technician | Q4: 3 | R4: Single | S4: 2090 | T4: 2396 | U4: 6 | V4: Y | W4: Yes | X4: 15 | Y4: 3 | Z4: 2 | AA4: 80 | AB4: 0 | AC4: 7 | AD4: 3 | AE4: 3 | AF4: 0 | AG4: 0 | AH4: 0 | AI4: 0 | AJ4: =IF(B4="Yes",1,0) -> 1 | AK4: =IF(W4="Yes",1,0) -> 1 | AL4: =IF(L4="Male",1,0) -> 1 | AM4: =AVERAGE(K4,Q4,Z4,AE4) -> 3 | AN4: =(S4*12)/(AF4+1) -> 25080 | AO4: =AF4/(AC4+1) -> 0 | AP4: =IF(A4<30,"Under 30",IF(A4<40,"30-39",IF(A4<50,"40-49","50+"))) -> 30-39 | AQ4: =IF(S4<=$AV$1,"Low",IF(S4<=$AV$2,"Medium",IF(S4<=$AV$3,"High","Very High"))) -> Low | AR4: =IF(F4<=5,"Short",IF(F4<=15,"Medium","Long")) -> Short | AS4: =IF(C4="Travel_Frequently",1,0) -> 0
A5: 33 | B5: No | C5: Travel_Frequently | D5: 1392 | E5: Research & Development | F5: 3 | G5: 4 | H5: Life Sciences | I5: 1 | J5: 5 | K5: 4 | L5: Female | M5: 56 | N5: 3 | O5: 1 | P5: Research Scientist | Q5: 3 | R5: Married | S5: 2909 | T5: 23159 | U5: 1 | V5: Y | W5: Yes | X5: 11 | Y5: 3 | Z5: 3 | AA5: 80 | AB5: 0 | AC5: 8 | AD5: 3 | AE5: 3 | AF5: 8 | AG5: 7 | AH5: 3 | AI5: 0 | AJ5: =IF(B5="Yes",1,0) -> 0 | AK5: =IF(W5="Yes",1,0) -> 1 | AL5: =IF(L5="Male",1,0) -> 0 | AM5: =AVERAGE(K5,Q5,Z5,AE5) -> 3.25 | AN5: =(S5*12)/(AF5+1) -> 3878.6667 | AO5: =AF5/(AC5+1) -> 0.88888889 | AP5: =IF(A5<30,"Under 30",IF(A5<40,"30-39",IF(A5<50,"40-49","50+"))) -> 30-39 | AQ5: =IF(S5<=$AV$1,"Low",IF(S5<=$AV$2,"Medium",IF(S5<=$AV$3,"High","Very High"))) -> Medium | AR5: =IF(F5<=5,"Short",IF(F5<=15,"Medium","Long")) -> Short | AS5: =IF(C5="Travel_Frequently",1,0) -> 1
A6: 27 | B6: No | C6: Travel_Rarely | D6: 591 | E6: Research & Development | F6: 2 | G6: 1 | H6: Medical | I6: 1 | J6: 7 | K6: 1 | L6: Male | M6: 40 | N6: 3 | O6: 1 | P6: Laboratory Technician | Q6: 2 | R6: Married | S6: 3468 | T6: 16632 | U6: 9 | V6: Y | W6: No | X6: 12 | Y6: 3 | Z6: 4 | AA6: 80 | AB6: 1 | AC6: 6 | AD6: 3 | AE6: 3 | AF6: 2 | AG6: 2 | AH6: 2 | AI6: 2 | AJ6: =IF(B6="Yes",1,0) -> 0 | AK6: =IF(W6="Yes",1,0) -> 0 | AL6: =IF(L6="Male",1,0) -> 1 | AM6: =AVERAGE(K6,Q6,Z6,AE6) -> 2.5 | AN6: =(S6*12)/(AF6+1) -> 13872 | AO6: =AF6/(AC6+1) -> 0.28571429 | AP6: =IF(A6<30,"Under 30",IF(A6<40,"30-39",IF(A6<50,"40-49","50+"))) -> Under 30 | AQ6: =IF(S6<=$AV$1,"Low",IF(S6<=$AV$2,"Medium",IF(S6<=$AV$3,"High","Very High"))) -> Medium | AR6: =IF(F6<=5,"Short",IF(F6<=15,"Medium","Long")) -> Short | AS6: =IF(C6="Travel_Frequently",1,0) -> 0
A7: 32 | B7: No | C7: Travel_Frequently | D7: 1005 | E7: Research & Development | F7: 2 | G7: 2 | H7: Life Sciences | I7: 1 | J7: 8 | K7: 4 | L7: Male | M7: 79 | N7: 3 | O7: 1 | P7: Laboratory Technician | Q7: 4 | R7: Single | S7: 3068 | T7: 11864 | U7: 0 | V7: Y | W7: No | X7: 13 | Y7: 3 | Z7: 3 | AA7: 80 | AB7: 0 | AC7: 8 | AD7: 2 | AE7: 2 | AF7: 7 | AG7: 7 | AH7: 3 | AI7: 6 | AJ7: =IF(B7="Yes",1,0) -> 0 | AK7: =IF(W7="Yes",1,0) -> 0 | AL7: =IF(L7="Male",1,0) -> 1 | AM7: =AVERAGE(K7,Q7,Z7,AE7) -> 3.25 | AN7: =(S7*12)/(AF7+1) -> 4602 | AO7: =AF7/(AC7+1) -> 0.77777778 | AP7: =IF(A7<30,"Under 30",IF(A7<40,"30-39",IF(A7<50,"40-49","50+"))) -> 30-39 | AQ7: =IF(S7<=$AV$1,"Low",IF(S7<=$AV$2,"Medium",IF(S7<=$AV$3,"High","Very High"))) -> Medium | AR7: =IF(F7<=5,"Short",IF(F7<=15,"Medium","Long")) -> Short | AS7: =IF(C7="Travel_Frequently",1,0) -> 1
A8: 59 | B8: No | C8: Travel_Rarely | D8: 1324 | E8: Research & Development | F8: 3 | G8: 3 | H8: Medical | I8: 1 | J8: 10 | K8: 3 | L8: Female | M8: 81 | N8: 4 | O8: 1 | P8: Laboratory Technician | Q8: 1 | R8: Married | S8: 2670 | T8: 9964 | U8: 4 | V8: Y | W8: Yes | X8: 20 | Y8: 4 | Z8: 1 | AA8: 80 | AB8: 3 | AC8: 12 | AD8: 3 | AE8: 2 | AF8: 1 | AG8: 0 | AH8: 0 | AI8: 0 | AJ8: =IF(B8="Yes",1,0) -> 0 | AK8: =IF(W8="Yes",1,0) -> 1 | AL8: =IF(L8="Male",1,0) -> 0 | AM8: =AVERAGE(K8,Q8,Z8,AE8) -> 1.75 | AN8: =(S8*12)/(AF8+1) -> 16020 | AO8: =AF8/(AC8+1) -> 0.076923077 | AP8: =IF(A8<30,"Under 30",IF(A8<40,"30-39",IF(A8<50,"40-49","50+"))) -> 50+ | AQ8: =IF(S8<=$AV$1,"Low",IF(S8<=$AV$2,"Medium",IF(S8<=$AV$3,"High","Very High"))) -> Low | AR8: =IF(F8<=5,"Short",IF(F8<=15,"Medium","Long")) -> Short | AS8: =IF(C8="Travel_Frequently",1,0) -> 0
A9: 30 | B9: No | C9: Travel_Rarely | D9: 1358 | E9: Research & Development | F9: 24 | G9: 1 | H9: Life Sciences | I9: 1 | J9: 11 | K9: 4 | L9: Male | M9: 67 | N9: 3 | O9: 1 | P9: Laboratory Technician | Q9: 3 | R9: Divorced | S9: 2693 | T9: 13335 | U9: 1 | V9: Y | W9: No | X9: 22 | Y9: 4 | Z9: 2 | AA9: 80 | AB9: 1 | AC9: 1 | AD9: 2 | AE9: 3 | AF9: 1 | AG9: 0 | AH9: 0 | AI9: 0 | AJ9: =IF(B9="Yes",1,0) -> 0 | AK9: =IF(W9="Yes",1,0) -> 0 | AL9: =IF(L9="Male",1,0) -> 1 | AM9: =AVERAGE(K9,Q9,Z9,AE9) -> 3 | AN9: =(S9*12)/(AF9+1) -> 16158 | AO9: =AF9/(AC9+1) -> 0.5 | AP9: =IF(A9<30,"Under 30",IF(A9<40,"30-39",IF(A9<50,"40-49","50+"))) -> 30-39 | AQ9: =IF(S9<=$AV$1,"Low",IF(S9<=$AV$2,"Medium",IF(S9<=$AV$3,"High","Very High"))) -> Low | AR9: =IF(F9<=5,"Short",IF(F9<=15,"Medium","Long")) -> Long | AS9: =IF(C9="Travel_Frequently",1,0) -> 0
A10: 38 | B10: No | C10: Travel_Frequently | D10: 216 | E10: Research & Development | F10: 23 | G10: 3 | H10: Life Sciences | I10: 1 | J10: 12 | K10: 4 | L10: Male | M10: 44 | N10: 2 | O10: 3 | P10: Manufacturing Director | Q10: 3 | R10: Single | S10: 9526 | T10: 8787 | U10: 0 | V10: Y | W10: No | X10: 21 | Y10: 4 | Z10: 2 | AA10: 80 | AB10: 0 | AC10: 10 | AD10: 2 | AE10: 3 | AF10: 9 | AG10: 7 | AH10: 1 | AI10: 8 | AJ10: =IF(B10="Yes",1,0) -> 0 | AK10: =IF(W10="Yes",1,0) -> 0 | AL10: =IF(L10="Male",1,0) -> 1 | AM10: =AVERAGE(K10,Q10,Z10,AE10) -> 3 | AN10: =(S10*12)/(AF10+1) -> 11431.2 | AO10: =AF10/(AC10+1) -> 0.81818182 | AP10: =IF(A10<30,"Under 30",IF(A10<40,"30-39",IF(A10<50,"40-49","50+"))) -> 30-39 | AQ10: =IF(S10<=$AV$1,"Low",IF(S10<=$AV$2,"Medium",IF(S10<=$AV$3,"High","Very High"))) -> Very High | AR10: =IF(F10<=5,"Short",IF(F10<=15,"Medium","Long")) -> Long | AS10: =IF(C10="Travel_Frequently",1,0) -> 1
A11: 36 | B11: No | C11: Travel_Rarely | D11: 1299 | E11: Research & Development | F11: 27 | G11: 3 | H11: Medical | I11: 1 | J11: 13 | K11: 3 | L11: Male | M11: 94 | N11: 3 | O11: 2 | P11: Healthcare Representative | Q11: 3 | R11: Married | S11: 5237 | T11: 16577 | U11: 6 | V11: Y | W11: No | X11: 13 | Y11: 3 | Z11: 2 | AA11: 80 | AB11: 2 | AC11: 17 | AD11: 3 | AE11: 2 | AF11: 7 | AG11: 7 | AH11: 7 | AI11: 7 | AJ11: =IF(B11="Yes",1,0) -> 0 | AK11: =IF(W11="Yes",1,0) -> 0 | AL11: =IF(L11="Male",1,0) -> 1 | AM11: =AVERAGE(K11,Q11,Z11,AE11) -> 2.5 | AN11: =(S11*12)/(AF11+1) -> 7855.5 | AO11: =AF11/(AC11+1) -> 0.38888889 | AP11: =IF(A11<30,"Under 30",IF(A11<40,"30-39",IF(A11<50,"40-49","50+"))) -> 30-39 | AQ11: =IF(S11<=$AV$1,"Low",IF(S11<=$AV$2,"Medium",IF(S11<=$AV$3,"High","Very High"))) -> High | AR11: =IF(F11<=5,"Short",IF(F11<=15,"Medium","Long")) -> Long | AS11: =IF(C11="Travel_Frequently",1,0) -> 0
A12: 35 | B12: No | C12: Travel_Rarely | D12: 809 | E12: Research & Development | F12: 16 | G12: 3 | H12: Medical | I12: 1 | J12: 14 | K12: 1 | L12: Male | M12: 84 | N12: 4 | O12: 1 | P12: Laboratory Technician | Q12: 2 | R12: Married | S12: 2674 | T12: 16479 | U12: 0 | V12: Y | W12: No | X12: 13 | Y12: 3 | Z12: 3 | AA12: 80 | AB12: 1 | AC12: 6 | AD12: 5 | AE12: 3 | AF12: 5 | AG12: 4 | AH12: 0 | AI12: 3 | AJ12: =IF(B12="Yes",1,0) -> 0 | AK12: =IF(W12="Yes",1,0) -> 0 | AL12: =IF(L12="Male",1,0) -> 1 | AM12: =AVERAGE(K12,Q12,Z12,AE12) -> 2.25 | AN12: =(S12*12)/(AF12+1) -> 5348 | AO12: =AF12/(AC12+1) -> 0.71428571 | AP12: =IF(A12<30,"Under 30",IF(A12<40,"30-39",IF(A12<50,"40-49","50+"))) -> 30-39 | AQ12: =IF(S12<=$AV$1,"Low",IF(S12<=$AV$2,"Medium",IF(S12<=$AV$3,"High","Very High"))) -> Low | AR12: =IF(F12<=5,"Short",IF(F12<=15,"Medium","Long")) -> Long | AS12: =IF(C12="Travel_Frequently",1,0) -> 0
A13: 29 | B13: No | C13: Travel_Rarely | D13: 153 | E13: Research & Development | F13: 15 | G13: 2 | H13: Life Sciences | I13: 1 | J13: 15 | K13: 4 | L13: Female | M13: 49 | N13: 2 | O13: 2 | P13: Laboratory Technician | Q13: 3 | R13: Single | S13: 4193 | T13: 12682 | U13: 0 | V13: Y | W13: Yes | X13: 12 | Y13: 3 | Z13: 4 | AA13: 80 | AB13: 0 | AC13: 10 | AD13: 3 | AE13: 3 | AF13: 9 | AG13: 5 | AH13: 0 | AI13: 8 | AJ13: =IF(B13="Yes",1,0) -> 0 | AK13: =IF(W13="Yes",1,0) -> 1 | AL13: =IF(L13="Male",1,0) -> 0 | AM13: =AVERAGE(K13,Q13,Z13,AE13) -> 3.5 | AN13: =(S13*12)/(AF13+1) -> 5031.6 | AO13: =AF13/(AC13+1) -> 0.81818182 | AP13: =IF(A13<30,"Under 30",IF(A13<40,"30-39",IF(A13<50,"40-49","50+"))) -> Under 30 | AQ13: =IF(S13<=$AV$1,"Low",IF(S13<=$AV$2,"Medium",IF(S13<=$AV$3,"High","Very High"))) -> Medium | AR13: =IF(F13<=5,"Short",IF(F13<=15,"Medium","Long")) -> Medium | AS13: =IF(C13="Travel_Frequently",1,0) -> 0
A14: 31 | B14: No | C14: Travel_Rarely | D14: 670 | E14: Research & Development | F14: 26 | G14: 1 | H14: Life Sciences | I14: 1 | J14: 16 | K14: 1 | L14: Male | M14: 31 | N14: 3 | O14: 1 | P14: Research Scientist | Q14: 3 | R14: Divorced | S14: 2911 | T14: 15170 | U14: 1 | V14: Y | W14: No | X14: 17 | Y14: 3 | Z14: 4 | AA14: 80 | AB14: 1 | AC14: 5 | AD14: 1 | AE14: 2 | AF14: 5 | AG14: 2 | AH14: 4 | AI14: 3 | AJ14: =IF(B14="Yes",1,0) -> 0 | AK14: =IF(W14="Yes",1,0) -> 0 | AL14: =IF(L14="Male",1,0) -> 1 | AM14: =AVERAGE(K14,Q14,Z14,AE14) -> 2.5 | AN14: =(S14*12)/(AF14+1) -> 5822 | AO14: =AF14/(AC14+1) -> 0.83333333 | AP14: =IF(A14<30,"Under 30",IF(A14<40,"30-39",IF(A14<50,"40-49","50+"))) -> 30-39 | AQ14: =IF(S14<=$AV$1,"Low",IF(S14<=$AV$2,"Medium",IF(S14<=$AV$3,"High","Very High"))) -> Medium | AR14: =IF(F14<=5,"Short",IF(F14<=15,"Medium","Long")) -> Long | AS14: =IF(C14="Travel_Frequently",1,0) -> 0
A15: 34 | B15: No | C15: Travel_Rarely | D15: 1346 | E15: Research & Development | F15: 19 | G15: 2 | H15: Medical | I15: 1 | J15: 18 | K15: 2 | L15: Male | M15: 93 | N15: 3 | O15: 1 | P15: Laboratory Technician | Q15: 4 | R15: Divorced | S15: 2661 | T15: 8758 | U15: 0 | V15: Y | W15: No | X15: 11 | Y15: 3 | Z15: 3 | AA15: 80 | AB15: 1 | AC15: 3 | AD15: 2 | AE15: 3 | AF15: 2 | AG15: 2 | AH15: 1 | AI15: 2 | AJ15: =IF(B15="Yes",1,0) -> 0 | AK15: =IF(W15="Yes",1,0) -> 0 | AL15: =IF(L15="Male",1,0) -> 1 | AM15: =AVERAGE(K15,Q15,Z15,AE15) -> 3 | AN15: =(S15*12)/(AF15+1) -> 10644 | AO15: =AF15/(AC15+1) -> 0.5 | AP15: =IF(A15<30,"Under 30",IF(A15<40,"30-39",IF(A15<50,"40-49","50+"))) -> 30-39 | AQ15: =IF(S15<=$AV$1,"Low",IF(S15<=$AV$2,"Medium",IF(S15<=$AV$3,"High","Very High"))) -> Low | AR15: =IF(F15<=5,"Short",IF(F15<=15,"Medium","Long")) -> Long | AS15: =IF(C15="Travel_Frequently",1,0) -> 0
... A1471: 34 | B1471: No | C1471: Travel_Rarely | D1471: 628 | E1471: Research & Development | F1471: 8 | G1471: 3 | H1471: Medical | I1471: 1 | J1471: 2068 | K1471: 2 | L1471: Male | M1471: 82 | N1471: 4 | O1471: 2 | P1471: Laboratory Technician | Q1471: 3 | R1471: Married | S1471: 4404 | T1471: 10228 | U1471: 2 | V1471: Y | W1471: No | X1471: 12 | Y1471: 3 | Z1471: 1 | AA1471: 80 | AB1471: 0 | AC1471: 6 | AD1471: 3 | AE1471: 4 | AF1471: 4 | AG1471: 3 | AH1471: 1 | AI1471: 2 | AJ1471: =IF(B1471="Yes",1,0) -> 0 | AK1471: =IF(W1471="Yes",1,0) -> 0 | AL1471: =IF(L1471="Male",1,0) -> 1 | AM1471: =AVERAGE(K1471,Q1471,Z1471,AE1471) -> 2.5 | AN1471: =(S1471*12)/(AF1471+1) -> 10569.6 | AO1471: =AF1471/(AC1471+1) -> 0.57142857 | AP1471: =IF(A1471<30,"Under 30",IF(A1471<40,"30-39",IF(A1471<50,"40-49","50+"))) -> 30-39 | AQ1471: =IF(S1471<=$AV$1,"Low",IF(S1471<=$AV$2,"Medium",IF(S1471<=$AV$3,"High","Very High"))) -> Medium | AR1471: =IF(F1471<=5,"Short",IF(F1471<=15,"Medium","Long")) -> Medium | AS1471: =IF(C1471="Travel_Frequently",1,0) -> 0

Sheet EDA_Summary
A1: EXPLORATORY DATA ANALYSIS | M1: Attrition | N1: MonthlyIncome | P1: YearsAtCompany_Left | Q1: MonthlyIncome_Left | R1: YearsAtCompany_Stayed | S1: MonthlyIncome_Stayed | V1: Age Bin | W1: Employee Count | Y1: Department | Z1: AttritionRate | AB1: JobRole | AC1: AttritionRate | AE1: Status | AF1: Employees | AH1: TenureBucket | AI1: AttritionRate
M2: =Data_Cleaned!B2 -> Yes | N2: =Data_Cleaned!S2 -> 5993 | P2: {=_xlfn._xlws.FILTER(Data_Cleaned!AF2:AF1471,Data_Cleaned!B2:B1471="Yes")} -> 6 | Q2: {=_xlfn._xlws.FILTER(Data_Cleaned!S2:S1471,Data_Cleaned!B2:B1471="Yes")} -> 5993 | R2: {=_xlfn._xlws.FILTER(Data_Cleaned!AF2:AF1471,Data_Cleaned!B2:B1471="No")} -> 10 | S2: {=_xlfn._xlws.FILTER(Data_Cleaned!S2:S1471,Data_Cleaned!B2:B1471="No")} -> 5130 | V2: 18-24 | W2: =COUNTIFS(Data_Cleaned!$A$2:$A$1471,">=18",Data_Cleaned!$A$2:$A$1471,"<=24") -> 97 | Y2: =A40 -> Sales | Z2: =C40 -> 0.20898876 | AB2: =A53 -> Sales Executive | AC2: =C53 -> 0.17484663 | AE2: Left | AF2: =B31 -> 237 | AH2: =A89 -> 0-2 yrs | AI2: =C89 -> 0.29824561
A3: 1. DATASET DIMENSIONS | M3: =Data_Cleaned!B3 -> No | N3: =Data_Cleaned!S3 -> 5130 | P3: 0 | Q3: 2090 | R3: 8 | S3: 2909 | V3: 25-34 | W3: =COUNTIFS(Data_Cleaned!$A$2:$A$1471,">=25",Data_Cleaned!$A$2:$A$1471,"<=34") -> 553 | Y3: =A41 -> Research & Development | Z3: =C41 -> 0.13825364 | AB3: =A54 -> Research Scientist | AC3: =C54 -> 0.1609589 | AE3: Stayed | AF3: =B32 -> 1233 | AH3: =A90 -> 3-5 yrs | AI3: =C90 -> 0.13824885
A4: Rows (employees) | B4: =COUNTA(Data_Cleaned!A:A)-1 -> 1470 | M4: =Data_Cleaned!B4 -> Yes | N4: =Data_Cleaned!S4 -> 2090 | P4: 4 | Q4: 2028 | R4: 2 | S4: 3468 | V4: 35-44 | W4: =COUNTIFS(Data_Cleaned!$A$2:$A$1471,">=35",Data_Cleaned!$A$2:$A$1471,"<=44") -> 508 | Y4: =A42 -> Human Resources | Z4: =C42 -> 0.17460317 | AB4: =A55 -> Laboratory Technician | AC4: =C55 -> 0.23938224 | AH4: =A91 -> 6-10 yrs | AI4: =C91 -> 0.12276786
A5: Columns (base + engineered) | B5: =COUNTA(Data_Cleaned!1:1) -> 47 | M5: =Data_Cleaned!B5 -> No | N5: =Data_Cleaned!S5 -> 2909 | P5: 5 | Q5: 3407 | R5: 7 | S5: 3068 | V5: 45-54 | W5: =COUNTIFS(Data_Cleaned!$A$2:$A$1471,">=45",Data_Cleaned!$A$2:$A$1471,"<=54") -> 244 | AB5: =A56 -> Manufacturing Director | AC5: =C56 -> 0.068965517 | AH5: =A92 -> 11+ yrs | AI5: =C92 -> 0.081300813
A6: Numeric variables profiled below | B6: 14 | M6: =Data_Cleaned!B6 -> No | N6: =Data_Cleaned!S6 -> 3468 | P6: 4 | Q6: 2960 | R6: 1 | S6: 2670 | V6: 55+ | W6: =COUNTIFS(Data_Cleaned!$A$2:$A$1471,">=55") -> 68 | AB6: =A57 -> Healthcare Representative | AC6: =C57 -> 0.06870229
M7: =Data_Cleaned!B7 -> No | N7: =Data_Cleaned!S7 -> 3068 | P7: 10 | Q7: 3919 | R7: 1 | S7: 2693 | AB7: =A58 -> Manager | AC7: =C58 -> 0.049019608
A8: 2. SUMMARY STATISTICS (key numeric variables) | M8: =Data_Cleaned!B8 -> No | N8: =Data_Cleaned!S8 -> 2670 | P8: 1 | Q8: 2086 | R8: 9 | S8: 9526 | AB8: =A59 -> Sales Representative | AC8: =C59 -> 0.39759036
A9: Variable | B9: Count | C9: Mean | D9: Median | E9: StdDev | F9: Min | G9: Max | H9: Q1 | I9: Q3 | M9: =Data_Cleaned!B9 -> No | N9: =Data_Cleaned!S9 -> 2693 | P9: 2 | Q9: 2293 | R9: 7 | S9: 5237 | AB9: =A60 -> Research Director | AC9: =C60 -> 0.025
A10: Age | B10: =COUNT(Data_Cleaned!A2:A1471) -> 1470 | C10: =AVERAGE(Data_Cleaned!A2:A1471) -> 36.894558 | D10: =MEDIAN(Data_Cleaned!A2:A1471) -> 36 | E10: =_xlfn.STDEV.S(Data_Cleaned!A2:A1471) -> 9.1097482 | F10: =MIN(Data_Cleaned!A2:A1471) -> 18 | G10: =MAX(Data_Cleaned!A2:A1471) -> 60 | H10: =_xlfn.QUARTILE.INC(Data_Cleaned!A2:A1471,1) -> 30 | I10: =_xlfn.QUARTILE.INC(Data_Cleaned!A2:A1471,3) -> 43 | M10: =Data_Cleaned!B10 -> No | N10: =Data_Cleaned!S10 -> 9526 | P10: 3 | Q10: 2683 | R10: 5 | S10: 2674 | AB10: =A61 -> Human Resources | AC10: =C61 -> 0.23076923
A11: DailyRate | B11: =COUNT(Data_Cleaned!D2:D1471) -> 1470 | C11: =AVERAGE(Data_Cleaned!D2:D1471) -> 802.48571 | D11: =MEDIAN(Data_Cleaned!D2:D1471) -> 802 | E11: =_xlfn.STDEV.S(Data_Cleaned!D2:D1471) -> 403.5091 | F11: =MIN(Data_Cleaned!D2:D1471) -> 102 | G11: =MAX(Data_Cleaned!D2:D1471) -> 1499 | H11: =_xlfn.QUARTILE.INC(Data_Cleaned!D2:D1471,1) -> 465 | I11: =_xlfn.QUARTILE.INC(Data_Cleaned!D2:D1471,3) -> 1157 | M11: =Data_Cleaned!B11 -> No | N11: =Data_Cleaned!S11 -> 5237 | P11: 1 | Q11: 2293 | R11: 9 | S11: 4193
A12: DistanceFromHome | B12: =COUNT(Data_Cleaned!F2:F1471) -> 1470 | C12: =AVERAGE(Data_Cleaned!F2:F1471) -> 9.1993197 | D12: =MEDIAN(Data_Cleaned!F2:F1471) -> 7 | E12: =_xlfn.STDEV.S(Data_Cleaned!F2:F1471) -> 8.1055242 | F12: =MIN(Data_Cleaned!F2:F1471) -> 1 | G12: =MAX(Data_Cleaned!F2:F1471) -> 29 | H12: =_xlfn.QUARTILE.INC(Data_Cleaned!F2:F1471,1) -> 2 | I12: =_xlfn.QUARTILE.INC(Data_Cleaned!F2:F1471,3) -> 14 | M12: =Data_Cleaned!B12 -> No | N12: =Data_Cleaned!S12 -> 2674 | P12: 22 | Q12: 19545 | R12: 5 | S12: 2911
A13: MonthlyIncome | B13: =COUNT(Data_Cleaned!S2:S1471) -> 1470 | C13: =AVERAGE(Data_Cleaned!S2:S1471) -> 6490.4286 | D13: =MEDIAN(Data_Cleaned!S2:S1471) -> 4919 | E13: =_xlfn.STDEV.S(Data_Cleaned!S2:S1471) -> 4700.4471 | F13: =MIN(Data_Cleaned!S2:S1471) -> 1009 | G13: =MAX(Data_Cleaned!S2:S1471) -> 19999 | H13: =_xlfn.QUARTILE.INC(Data_Cleaned!S2:S1471,1) -> 2905.25 | I13: =_xlfn.QUARTILE.INC(Data_Cleaned!S2:S1471,3) -> 8339.75 | M13: =Data_Cleaned!B13 -> No | N13: =Data_Cleaned!S13 -> 4193 | P13: 1 | Q13: 5381 | R13: 2 | S13: 2661
A14: NumCompaniesWorked | B14: =COUNT(Data_Cleaned!U2:U1471) -> 1470 | C14: =AVERAGE(Data_Cleaned!U2:U1471) -> 2.6945578 | D14: =MEDIAN(Data_Cleaned!U2:U1471) -> 2 | E14: =_xlfn.STDEV.S(Data_Cleaned!U2:U1471) -> 2.4970856 | F14: =MIN(Data_Cleaned!U2:U1471) -> 0 | G14: =MAX(Data_Cleaned!U2:U1471) -> 9 | H14: =_xlfn.QUARTILE.INC(Data_Cleaned!U2:U1471,1) -> 1 | I14: =_xlfn.QUARTILE.INC(Data_Cleaned!U2:U1471,3) -> 4 | M14: =Data_Cleaned!B14 -> No | N14: =Data_Cleaned!S14 -> 2911 | P14: 2 | Q14: 3441 | R14: 10 | S14: 9980
A15: PercentSalaryHike | B15: =COUNT(Data_Cleaned!X2:X1471) -> 1470 | C15: =AVERAGE(Data_Cleaned!X2:X1471) -> 15.204082 | D15: =MEDIAN(Data_Cleaned!X2:X1471) -> 14 | E15: =_xlfn.STDEV.S(Data_Cleaned!X2:X1471) -> 3.6576408 | F15: =MIN(Data_Cleaned!X2:X1471) -> 11 | G15: =MAX(Data_Cleaned!X2:X1471) -> 25 | H15: =_xlfn.QUARTILE.INC(Data_Cleaned!X2:X1471,1) -> 12 | I15: =_xlfn.QUARTILE.INC(Data_Cleaned!X2:X1471,3) -> 18 | M15: =Data_Cleaned!B15 -> No | N15: =Data_Cleaned!S15 -> 2661 | P15: 1 | Q15: 3388 | R15: 6 | S15: 3298
A16: TotalWorkingYears | B16: =COUNT(Data_Cleaned!AC2:AC1471) -> 1470 | C16: =AVERAGE(Data_Cleaned!AC2:AC1471) -> 11.303401 | D16: =MEDIAN(Data_Cleaned!AC2:AC1471) -> 10 | E16: =_xlfn.STDEV.S(Data_Cleaned!AC2:AC1471) -> 7.7667969 | F16: =MIN(Data_Cleaned!AC2:AC1471) -> 0 | G16: =MAX(Data_Cleaned!AC2:AC1471) -> 40 | H16: =_xlfn.QUARTILE.INC(Data_Cleaned!AC2:AC1471,1) -> 6 | I16: =_xlfn.QUARTILE.INC(Data_Cleaned!AC2:AC1471,3) -> 15 | M16: =Data_Cleaned!B16 -> Yes | N16: =Data_Cleaned!S16 -> 2028 | P16: 9 | Q16: 9619 | R16: 1 | S16: 2935
A17: TrainingTimesLastYear | B17: =COUNT(Data_Cleaned!AD2:AD1471) -> 1470 | C17: =AVERAGE(Data_Cleaned!AD2:AD1471) -> 2.7993197 | D17: =MEDIAN(Data_Cleaned!AD2:AD1471) -> 3 | E17: =_xlfn.STDEV.S(Data_Cleaned!AD2:AD1471) -> 1.2892706 | F17: =MIN(Data_Cleaned!AD2:AD1471) -> 0 | G17: =MAX(Data_Cleaned!AD2:AD1471) -> 6 | H17: =_xlfn.QUARTILE.INC(Data_Cleaned!AD2:AD1471,1) -> 2 | I17: =_xlfn.QUARTILE.INC(Data_Cleaned!AD2:AD1471,3) -> 3 | M17: =Data_Cleaned!B17 -> No | N17: =Data_Cleaned!S17 -> 9980 | P17: 3 | Q17: 2073 | R17: 25 | S17: 15427
A18: YearsAtCompany | B18: =COUNT(Data_Cleaned!AF2:AF1471) -> 1470 | C18: =AVERAGE(Data_Cleaned!AF2:AF1471) -> 7.0081633 | D18: =MEDIAN(Data_Cleaned!AF2:AF1471) -> 5 | E18: =_xlfn.STDEV.S(Data_Cleaned!AF2:AF1471) -> 6.1265252 | F18: =MIN(Data_Cleaned!AF2:AF1471) -> 0 | G18: =MAX(Data_Cleaned!AF2:AF1471) -> 40 | H18: =_xlfn.QUARTILE.INC(Data_Cleaned!AF2:AF1471,1) -> 3 | I18: =_xlfn.QUARTILE.INC(Data_Cleaned!AF2:AF1471,3) -> 9 | M18: =Data_Cleaned!B18 -> No | N18: =Data_Cleaned!S18 -> 3298 | P18: 1 | Q18: 2926 | R18: 3 | S18: 3944
A19: YearsInCurrentRole | B19: =COUNT(Data_Cleaned!AG2:AG1471) -> 1470 | C19: =AVERAGE(Data_Cleaned!AG2:AG1471) -> 4.2292517 | D19: =MEDIAN(Data_Cleaned!AG2:AG1471) -> 3 | E19: =_xlfn.STDEV.S(Data_Cleaned!AG2:AG1471) -> 3.623137 | F19: =MIN(Data_Cleaned!AG2:AG1471) -> 0 | G19: =MAX(Data_Cleaned!AG2:AG1471) -> 18 | H19: =_xlfn.QUARTILE.INC(Data_Cleaned!AG2:AG1471,1) -> 2 | I19: =_xlfn.QUARTILE.INC(Data_Cleaned!AG2:AG1471,3) -> 7 | M19: =Data_Cleaned!B19 -> No | N19: =Data_Cleaned!S19 -> 2935 | P19: 6 | Q19: 5744 | R19: 4 | S19: 4011
A20: YearsSinceLastPromotion | B20: =COUNT(Data_Cleaned!AH2:AH1471) -> 1470 | C20: =AVERAGE(Data_Cleaned!AH2:AH1471) -> 2.1877551 | D20: =MEDIAN(Data_Cleaned!AH2:AH1471) -> 1 | E20: =_xlfn.STDEV.S(Data_Cleaned!AH2:AH1471) -> 3.2224303 | F20: =MIN(Data_Cleaned!AH2:AH1471) -> 0 | G20: =MAX(Data_Cleaned!AH2:AH1471) -> 15 | H20: =_xlfn.QUARTILE.INC(Data_Cleaned!AH2:AH1471,1) -> 0 | I20: =_xlfn.QUARTILE.INC(Data_Cleaned!AH2:AH1471,3) -> 3 | M20: =Data_Cleaned!B20 -> No | N20: =Data_Cleaned!S20 -> 15427 | P20: 9 | Q20: 6074 | R20: 12 | S20: 11994
A21: JobSatisfaction | B21: =COUNT(Data_Cleaned!Q2:Q1471) -> 1470 | C21: =AVERAGE(Data_Cleaned!Q2:Q1471) -> 2.7285714 | D21: =MEDIAN(Data_Cleaned!Q2:Q1471) -> 3 | E21: =_xlfn.STDEV.S(Data_Cleaned!Q2:Q1471) -> 1.1028461 | F21: =MIN(Data_Cleaned!Q2:Q1471) -> 1 | G21: =MAX(Data_Cleaned!Q2:Q1471) -> 4 | H21: =_xlfn.QUARTILE.INC(Data_Cleaned!Q2:Q1471,1) -> 2 | I21: =_xlfn.QUARTILE.INC(Data_Cleaned!Q2:Q1471,3) -> 4 | M21: =Data_Cleaned!B21 -> No | N21: =Data_Cleaned!S21 -> 3944 | P21: 5 | Q21: 4963 | R21: 0 | S21: 1232
A22: EnvironmentSatisfaction | B22: =COUNT(Data_Cleaned!K2:K1471) -> 1470 | C22: =AVERAGE(Data_Cleaned!K2:K1471) -> 2.7272109 | D22: =MEDIAN(Data_Cleaned!K2:K1471) -> 3 | E22: =_xlfn.STDEV.S(Data_Cleaned!K2:K1471) -> 1.0894667 | F22: =MIN(Data_Cleaned!K2:K1471) -> 1 | G22: =MAX(Data_Cleaned!K2:K1471) -> 4 | H22: =_xlfn.QUARTILE.INC(Data_Cleaned!K2:K1471,1) -> 2 | I22: =_xlfn.QUARTILE.INC(Data_Cleaned!K2:K1471,3) -> 4 | M22: =Data_Cleaned!B22 -> No | N22: =Data_Cleaned!S22 -> 4011 | P22: 7 | Q22: 6172 | R22: 14 | S22: 19094
A23: WorkLifeBalance | B23: =COUNT(Data_Cleaned!AE2:AE1471) -> 1470 | C23: =AVERAGE(Data_Cleaned!AE2:AE1471) -> 2.7612245 | D23: =MEDIAN(Data_Cleaned!AE2:AE1471) -> 3 | E23: =_xlfn.STDEV.S(Data_Cleaned!AE2:AE1471) -> 0.70647583 | F23: =MIN(Data_Cleaned!AE2:AE1471) -> 1 | G23: =MAX(Data_Cleaned!AE2:AE1471) -> 4 | H23: =_xlfn.QUARTILE.INC(Data_Cleaned!AE2:AE1471,1) -> 2 | I23: =_xlfn.QUARTILE.INC(Data_Cleaned!AE2:AE1471,3) -> 3 | M23: =Data_Cleaned!B23 -> Yes | N23: =Data_Cleaned!S23 -> 3407 | P23: 40 | Q23: 10312 | R23: 9 | S23: 6825
M24: =Data_Cleaned!B24 -> No | N24: =Data_Cleaned!S24 -> 11994 | P24: 0 | Q24: 1675 | R24: 22 | S24: 10248
M25: =Data_Cleaned!B25 -> No | N25: =Data_Cleaned!S25 -> 1232 | P25: 2 | Q25: 4559 | R25: 2 | S25: 18947
A26: 3. MISSING VALUE ANALYSIS (post-cleaning) | M26: =Data_Cleaned!B26 -> Yes | N26: =Data_Cleaned!S26 -> 2960 | P26: 4 | Q26: 10650 | R26: 1 | S26: 2496
A27: Blank cells across all 35 base columns (Data_Cleaned!A2:AI1471) | B27: {=SUMPRODUCT(--(Data_Cleaned!A2:AI1471=""))} -> 0 | M27: =Data_Cleaned!B27 -> No | N27: =Data_Cleaned!S27 -> 19094 | P27: 5 | Q27: 4200 | R27: 4 | S27: 6465
